Workbook

Sheet Summary
A1: Zero Dose Digitization – District Follow-up Summary
A2: SNID Sept 2026 · IDIMS comparison report of 09-Oct-2026 · compared with SNID May 2026 (22-Jun-2026) · generated 09-Oct-2026 17:43
A4: District | B4: UCs | C4: ZD Reported | D4: ZD Linelist | E4: Completion % | F4: Children to enter | G4: P1 No entries | H4: P2 Critical | I4: P3 Verify | J4: P4 Low | K4: Total follow-ups | L4: Done (from status) | M4: May completion % | N4: Change (pts) | O4: Persistent low | P4: Newly declined | Q4: Recovered
A5: BANNU | B5: =COUNTIF('All UCs'!$B:$B,A5) -> 57 | C5: =SUMIF('All UCs'!$B:$B,A5,'All UCs'!$F:$F) -> 4205 | D5: =SUMIF('All UCs'!$B:$B,A5,'All UCs'!$G:$G) -> 3747 | E5: =IF(C5>0,D5/C5,0) -> 0.89108205 | F5: =SUMIF('All Follow-ups'!$A:$A,A5,'All Follow-ups'!$I:$I) -> 748 | G5: =COUNTIFS('All Follow-ups'!$A:$A,A5,'All Follow-ups'!$B:$B,"P1*") -> 4 | H5: =COUNTIFS('All Follow-ups'!$A:$A,A5,'All Follow-ups'!$B:$B,"P2*") -> 0 | I5: =COUNTIFS('All Follow-ups'!$A:$A,A5,'All Follow-ups'!$B:$B,"P3*") -> 9 | J5: =COUNTIFS('All Follow-ups'!$A:$A,A5,'All Follow-ups'!$B:$B,"P4*") -> 10 | K5: =SUM(G5:J5) -> 23 | L5: =COUNTIF('BANNU'!$O:$O,"Done") -> 0 | M5: =IFERROR(SUMIF('All UCs'!$B:$B,A5,'All UCs'!$L:$L)/SUMIF('All UCs'!$B:$B,A5,'All UCs'!$K:$K),0) -> 0.74135021 | N5: =(E5-M5)*100 -> 14.973183 | O5: =COUNTIFS('All UCs'!$B:$B,A5,'All UCs'!$O:$O,"Persistent low") -> 5 | P5: =COUNTIFS('All UCs'!$B:$B,A5,'All UCs'!$O:$O,"Newly declined") -> 9 | Q5: =COUNTIFS('All UCs'!$B:$B,A5,'All UCs'!$O:$O,"Recovered") -> 14
A6: TANK | B6: =COUNTIF('All UCs'!$B:$B,A6) -> 22 | C6: =SUMIF('All UCs'!$B:$B,A6,'All UCs'!$F:$F) -> 967 | D6: =SUMIF('All UCs'!$B:$B,A6,'All UCs'!$G:$G) -> 871 | E6: =IF(C6>0,D6/C6,0) -> 0.90072389 | F6: =SUMIF('All Follow-ups'!$A:$A,A6,'All Follow-ups'!$I:$I) -> 150 | G6: =COUNTIFS('All Follow-ups'!$A:$A,A6,'All Follow-ups'!$B:$B,"P1*") -> 3 | H6: =COUNTIFS('All Follow-ups'!$A:$A,A6,'All Follow-ups'!$B:$B,"P2*") -> 1 | I6: =COUNTIFS('All Follow-ups'!$A:$A,A6,'All Follow-ups'!$B:$B,"P3*") -> 1 | J6: =COUNTIFS('All Follow-ups'!$A:$A,A6,'All Follow-ups'!$B:$B,"P4*") -> 2 | K6: =SUM(G6:J6) -> 7 | L6: =COUNTIF('TANK'!$O:$O,"Done") -> 0 | M6: =IFERROR(SUMIF('All UCs'!$B:$B,A6,'All UCs'!$L:$L)/SUMIF('All UCs'!$B:$B,A6,'All UCs'!$K:$K),0) -> 0.97841727 | N6: =(E6-M6)*100 -> -7.7693378 | O6: =COUNTIFS('All UCs'!$B:$B,A6,'All UCs'!$O:$O,"Persistent low") -> 0 | P6: =COUNTIFS('All UCs'!$B:$B,A6,'All UCs'!$O:$O,"Newly declined") -> 6 | Q6: =COUNTIFS('All UCs'!$B:$B,A6,'All UCs'!$O:$O,"Recovered") -> 2
A7: WAZIR-S Lower | B7: =COUNTIF('All UCs'!$B:$B,A7) -> 36 | C7: =SUMIF('All UCs'!$B:$B,A7,'All UCs'!$F:$F) -> 572 | D7: =SUMIF('All UCs'!$B:$B,A7,'All UCs'!$G:$G) -> 517 | E7: =IF(C7>0,D7/C7,0) -> 0.90384615 | F7: =SUMIF('All Follow-ups'!$A:$A,A7,'All Follow-ups'!$I:$I) -> 112 | G7: =COUNTIFS('All Follow-ups'!$A:$A,A7,'All Follow-ups'!$B:$B,"P1*") -> 6 | H7: =COUNTIFS('All Follow-ups'!$A:$A,A7,'All Follow-ups'!$B:$B,"P2*") -> 0 | I7: =COUNTIFS('All Follow-ups'!$A:$A,A7,'All Follow-ups'!$B:$B,"P3*") -> 11 | J7: =COUNTIFS('All Follow-ups'!$A:$A,A7,'All Follow-ups'!$B:$B,"P4*") -> 3 | K7: =SUM(G7:J7) -> 20 | L7: =COUNTIF('WAZIR-S Lower'!$O:$O,"Done") -> 0 | M7: =IFERROR(SUMIF('All UCs'!$B:$B,A7,'All UCs'!$L:$L)/SUMIF('All UCs'!$B:$B,A7,'All UCs'!$K:$K),0) -> 0.99425287 | N7: =(E7-M7)*100 -> -9.040672 | O7: =COUNTIFS('All UCs'!$B:$B,A7,'All UCs'!$O:$O,"Persistent low") -> 2 | P7: =COUNTIFS('All UCs'!$B:$B,A7,'All UCs'!$O:$O,"Newly declined") -> 7 | Q7: =COUNTIFS('All UCs'!$B:$B,A7,'All UCs'!$O:$O,"Recovered") -> 1
A8: PESHAWAR | B8: =COUNTIF('All UCs'!$B:$B,A8) -> 103 | C8: =SUMIF('All UCs'!$B:$B,A8,'All UCs'!$F:$F) -> 13547 | D8: =SUMIF('All UCs'!$B:$B,A8,'All UCs'!$G:$G) -> 12681 | E8: =IF(C8>0,D8/C8,0) -> 0.93607441 | F8: =SUMIF('All Follow-ups'!$A:$A,A8,'All Follow-ups'!$I:$I) -> 1010 | G8: =COUNTIFS('All Follow-ups'!$A:$A,A8,'All Follow-ups'!$B:$B,"P1*") -> 5 | H8: =COUNTIFS('All Follow-ups'!$A:$A,A8,'All Follow-ups'!$B:$B,"P2*") -> 0 | I8: =COUNTIFS('All Follow-ups'!$A:$A,A8,'All Follow-ups'!$B:$B,"P3*") -> 4 | J8: =COUNTIFS('All Follow-ups'!$A:$A,A8,'All Follow-ups'!$B:$B,"P4*") -> 7 | K8: =SUM(G8:J8) -> 16 | L8: =COUNTIF('PESHAWAR'!$O:$O,"Done") -> 0 | M8: =IFERROR(SUMIF('All UCs'!$B:$B,A8,'All UCs'!$L:$L)/SUMIF('All UCs'!$B:$B,A8,'All UCs'!$K:$K),0) -> 0.47366846 | N8: =(E8-M8)*100 -> 46.240595 | O8: =COUNTIFS('All UCs'!$B:$B,A8,'All UCs'!$O:$O,"Persistent low") -> 9 | P8: =COUNTIFS('All UCs'!$B:$B,A8,'All UCs'!$O:$O,"Newly declined") -> 3 | Q8: =COUNTIFS('All UCs'!$B:$B,A8,'All UCs'!$O:$O,"Recovered") -> 72
A9: DIKHAN | B9: =COUNTIF('All UCs'!$B:$B,A9) -> 53 | C9: =SUMIF('All UCs'!$B:$B,A9,'All UCs'!$F:$F) -> 5284 | D9: =SUMIF('All UCs'!$B:$B,A9,'All UCs'!$G:$G) -> 5010 | E9: =IF(C9>0,D9/C9,0) -> 0.94814534 | F9: =SUMIF('All Follow-ups'!$A:$A,A9,'All Follow-ups'!$I:$I) -> 247 | G9: =COUNTIFS('All Follow-ups'!$A:$A,A9,'All Follow-ups'!$B:$B,"P1*") -> 2 | H9: =COUNTIFS('All Follow-ups'!$A:$A,A9,'All Follow-ups'!$B:$B,"P2*") -> 2 | I9: =COUNTIFS('All Follow-ups'!$A:$A,A9,'All Follow-ups'!$B:$B,"P3*") -> 3 | J9: =COUNTIFS('All Follow-ups'!$A:$A,A9,'All Follow-ups'!$B:$B,"P4*") -> 5 | K9: =SUM(G9:J9) -> 12 | L9: =COUNTIF('DIKHAN'!$O:$O,"Done") -> 0 | M9: =IFERROR(SUMIF('All UCs'!$B:$B,A9,'All UCs'!$L:$L)/SUMIF('All UCs'!$B:$B,A9,'All UCs'!$K:$K),0) -> 0.89848653 | N9: =(E9-M9)*100 -> 4.9658818 | O9: =COUNTIFS('All UCs'!$B:$B,A9,'All UCs'!$O:$O,"Persistent low") -> 3 | P9: =COUNTIFS('All UCs'!$B:$B,A9,'All UCs'!$O:$O,"Newly declined") -> 6 | Q9: =COUNTIFS('All UCs'!$B:$B,A9,'All UCs'!$O:$O,"Recovered") -> 7
A10: LAKKIMRWT | B10: =COUNTIF('All UCs'!$B:$B,A10) -> 40 | C10: =SUMIF('All UCs'!$B:$B,A10,'All UCs'!$F:$F) -> 4555 | D10: =SUMIF('All UCs'!$B:$B,A10,'All UCs'!$G:$G) -> 4560 | E10: =IF(C10>0,D10/C10,0) -> 1.0010977 | F10: =SUMIF('All Follow-ups'!$A:$A,A10,'All Follow-ups'!$I:$I) -> 139 | G10: =COUNTIFS('All Follow-ups'!$A:$A,A10,'All Follow-ups'!$B:$B,"P1*") -> 0 | H10: =COUNTIFS('All Follow-ups'!$A:$A,A10,'All Follow-ups'!$B:$B,"P2*") -> 0 | I10: =COUNTIFS('All Follow-ups'!$A:$A,A10,'All Follow-ups'!$B:$B,"P3*") -> 5 | J10: =COUNTIFS('All Follow-ups'!$A:$A,A10,'All Follow-ups'!$B:$B,"P4*") -> 5 | K10: =SUM(G10:J10) -> 10 | L10: =COUNTIF('LAKKIMRWT'!$O:$O,"Done") -> 0 | M10: =IFERROR(SUMIF('All UCs'!$B:$B,A10,'All UCs'!$L:$L)/SUMIF('All UCs'!$B:$B,A10,'All UCs'!$K:$K),0) -> 1 | N10: =(E10-M10)*100 -> 0.10976948 | O10: =COUNTIFS('All UCs'!$B:$B,A10,'All UCs'!$O:$O,"Persistent low") -> 0 | P10: =COUNTIFS('All UCs'!$B:$B,A10,'All UCs'!$O:$O,"Newly declined") -> 5 | Q10: =COUNTIFS('All UCs'!$B:$B,A10,'All UCs'!$O:$O,"Recovered") -> 0
A11: KHYBER | B11: =COUNTIF('All UCs'!$B:$B,A11) -> 53 | C11: =SUMIF('All UCs'!$B:$B,A11,'All UCs'!$F:$F) -> 1850 | D11: =SUMIF('All UCs'!$B:$B,A11,'All UCs'!$G:$G) -> 1863 | E11: =IF(C11>0,D11/C11,0) -> 1.007027 | F11: =SUMIF('All Follow-ups'!$A:$A,A11,'All Follow-ups'!$I:$I) -> 35 | G11: =COUNTIFS('All Follow-ups'!$A:$A,A11,'All Follow-ups'!$B:$B,"P1*") -> 1 | H11: =COUNTIFS('All Follow-ups'!$A:$A,A11,'All Follow-ups'!$B:$B,"P2*") -> 0 | I11: =COUNTIFS('All Follow-ups'!$A:$A,A11,'All Follow-ups'!$B:$B,"P3*") -> 6 | J11: =COUNTIFS('All Follow-ups'!$A:$A,A11,'All Follow-ups'!$B:$B,"P4*") -> 2 | K11: =SUM(G11:J11) -> 9 | L11: =COUNTIF('KHYBER'!$O:$O,"Done") -> 0 | M11: =IFERROR(SUMIF('All UCs'!$B:$B,A11,'All UCs'!$L:$L)/SUMIF('All UCs'!$B:$B,A11,'All UCs'!$K:$K),0) -> 0.9212766 | N11: =(E11-M11)*100 -> 8.5750431 | O11: =COUNTIFS('All UCs'!$B:$B,A11,'All UCs'!$O:$O,"Persistent low") -> 0 | P11: =COUNTIFS('All UCs'!$B:$B,A11,'All UCs'!$O:$O,"Newly declined") -> 3 | Q11: =COUNTIFS('All UCs'!$B:$B,A11,'All UCs'!$O:$O,"Recovered") -> 5
A12: WAZIR-N | B12: =COUNTIF('All UCs'!$B:$B,A12) -> 23 | C12: =SUMIF('All UCs'!$B:$B,A12,'All UCs'!$F:$F) -> 492 | D12: =SUMIF('All UCs'!$B:$B,A12,'All UCs'!$G:$G) -> 537 | E12: =IF(C12>0,D12/C12,0) -> 1.0914634 | F12: =SUMIF('All Follow-ups'!$A:$A,A12,'All Follow-ups'!$I:$I) -> 155 | G12: =COUNTIFS('All Follow-ups'!$A:$A,A12,'All Follow-ups'!$B:$B,"P1*") -> 6 | H12: =COUNTIFS('All Follow-ups'!$A:$A,A12,'All Follow-ups'!$B:$B,"P2*") -> 1 | I12: =COUNTIFS('All Follow-ups'!$A:$A,A12,'All Follow-ups'!$B:$B,"P3*") -> 7 | J12: =COUNTIFS('All Follow-ups'!$A:$A,A12,'All Follow-ups'!$B:$B,"P4*") -> 1 | K12: =SUM(G12:J12) -> 15 | L12: =COUNTIF('WAZIR-N'!$O:$O,"Done") -> 0 | M12: =IFERROR(SUMIF('All UCs'!$B:$B,A12,'All UCs'!$L:$L)/SUMIF('All UCs'!$B:$B,A12,'All UCs'!$K:$K),0) -> 1 | N12: =(E12-M12)*100 -> 9.1463415 | O12: =COUNTIFS('All UCs'!$B:$B,A12,'All UCs'!$O:$O,"Persistent low") -> 0 | P12: =COUNTIFS('All UCs'!$B:$B,A12,'All UCs'!$O:$O,"Newly declined") -> 5 | Q12: =COUNTIFS('All UCs'!$B:$B,A12,'All UCs'!$O:$O,"Recovered") -> 0
A13: WAZIR-S Upper | B13: =COUNTIF('All UCs'!$B:$B,A13) -> 34 | C13: =SUMIF('All UCs'!$B:$B,A13,'All UCs'!$F:$F) -> 290 | D13: =SUMIF('All UCs'!$B:$B,A13,'All UCs'!$G:$G) -> 346 | E13: =IF(C13>0,D13/C13,0) -> 1.1931034 | F13: =SUMIF('All Follow-ups'!$A:$A,A13,'All Follow-ups'!$I:$I) -> 15 | G13: =COUNTIFS('All Follow-ups'!$A:$A,A13,'All Follow-ups'!$B:$B,"P1*") -> 3 | H13: =COUNTIFS('All Follow-ups'!$A:$A,A13,'All Follow-ups'!$B:$B,"P2*") -> 0 | I13: =COUNTIFS('All Follow-ups'!$A:$A,A13,'All Follow-ups'!$B:$B,"P3*") -> 8 | J13: =COUNTIFS('All Follow-ups'!$A:$A,A13,'All Follow-ups'!$B:$B,"P4*") -> 1 | K13: =SUM(G13:J13) -> 12 | L13: =COUNTIF('WAZIR-S Upper'!$O:$O,"Done") -> 0 | M13: =IFERROR(SUMIF('All UCs'!$B:$B,A13,'All UCs'!$L:$L)/SUMIF('All UCs'!$B:$B,A13,'All UCs'!$K:$K),0) -> 0.14285714 | N13: =(E13-M13)*100 -> 105.02463 | O13: =COUNTIFS('All UCs'!$B:$B,A13,'All UCs'!$O:$O,"Persistent low") -> 1 | P13: =COUNTIFS('All UCs'!$B:$B,A13,'All UCs'!$O:$O,"Newly declined") -> 0 | Q13: =COUNTIFS('All UCs'!$B:$B,A13,'All UCs'!$O:$O,"Recovered") -> 8
A14: Total | B14: =SUM(B5:B13) -> 421 | C14: =SUM(C5:C13) -> 31762 | D14: =SUM(D5:D13) -> 30132 | E14: =IF(C14>0,D14/C14,0) -> 0.94868081 | F14: =SUM(F5:F13) -> 2611 | G14: =SUM(G5:G13) -> 30 | H14: =SUM(H5:H13) -> 4 | I14: =SUM(I5:I13) -> 54 | J14: =SUM(J5:J13) -> 36 | K14: =SUM(K5:K13) -> 124 | L14: =SUM(L5:L13) -> 0 | M14: =IFERROR(SUM('All UCs'!$L:$L)/SUM('All UCs'!$K:$K),0) -> 0.68654123 | N14: =(E14-M14)*100 -> 26.213958 | O14: =SUM(O5:O13) -> 20 | P14: =SUM(P5:P13) -> 44 | Q14: =SUM(Q5:Q13) -> 109
A16: Priority key and action
A17: Priority | B17: Rule | C17: Action for district team
A18: P1 – No entries | B18: IDIMS reported > 0 but linelist entries = 0 | C18: No linelist entries yet. Confirm a data-entry person is assigned and start entry.
A19: P2 – Critical (<50%) | B19: Completion below 50% | C19: Less than half entered. Complete the remaining linelist entries.
A20: P3 – Verify: over-entry | B20: Completion above 110% | C20: Entries exceed the IDIMS figure by more than 10%. Check for duplicate entries and cross-check the IDIMS number.
A21: P3 – Verify: no IDIMS figure | B21: IDIMS = 0 but linelist has entries | C21: Linelist has entries but IDIMS reports 0 ZDs. Verify IDIMS reporting for this UC.
A22: P3 – Verify: duplicates | B22: Duplicate records flagged (UC otherwise on track) | C22: Duplicate records flagged in the report. Review and remove duplicates.
A23: P4 – Low (50–80%) | B23: Completion 50–80% | C23: Complete the remaining linelist entries.
A25: How to use: each district sheet lists only that district's UCs needing follow-up, sorted by priority then by children still to enter.
A26: District teams fill in the green columns (Responsible person, Target date, Status, Remarks). "Done" counts update on this Summary automatically.
A27: UCs at 80–110% with no duplicates are on track and are not listed; see the All UCs sheet for the full list.
A28: Trend compares with SNID May 2026 (report of 22-Jun-2026) using the 80% line: Persistent low = below 80% in both; Newly declined = 80%+ then, below 80% now; Recovered = below 80% then, 80%+ now; Not comparable = IDIMS reported 0 in either campaign.

Sheet All Follow-ups
A1: Zero Dose Digitization – Follow-up List (all districts)
A2: SNID Sept 2026 · 124 UCs needing follow-up · IDIMS comparison report of 09-Oct-2026 · Trend vs SNID May 2026 (22-Jun-2026) · Green columns are for district teams to fill in
A4: District | B4: Priority | C4: Tehsil | D4: UC | E4: UC Code | F4: ZD Reported | G4: ZD Linelist | H4: Completion % | I4: Children to enter | J4: Excess entries | K4: May completion % | L4: Trend May→Sept | M4: Action required | N4: Responsible person | O4: Target date | P4: Status | Q4: Remarks
A5: BANNU | B5: P1 – No entries | C5: KAKKI | D5: KAKKI 1 | E5: 36106002 | F5: 135 | G5: 0 | H5: =IF(F5>0,G5/F5,"n/a") -> 0 | I5: =MAX(F5-G5,0) -> 135 | J5: =MAX(G5-F5,0) -> 0 | K5: 0.979 | L5: Newly declined | M5: No linelist entries yet. Confirm a data-entry person is assigned and start entry. Was on track in May: check that data-entry staff are in place. | P5: Not started
A6: BANNU | B6: P1 – No entries | C6: BANNU | D6: LALO ZAI | E6: 36101023 | F6: 120 | G6: 0 | H6: =IF(F6>0,G6/F6,"n/a") -> 0 | I6: =MAX(F6-G6,0) -> 120 | J6: =MAX(G6-F6,0) -> 0 | K6: 1 | L6: Newly declined | M6: No linelist entries yet. Confirm a data-entry person is assigned and start entry. Was on track in May: check that data-entry staff are in place. | P6: Not started
A7: BANNU | B7: P1 – No entries | C7: KAKKI | D7: NAR SHUKRULLAH | E7: 36106006 | F7: 111 | G7: 0 | H7: =IF(F7>0,G7/F7,"n/a") -> 0 | I7: =MAX(F7-G7,0) -> 111 | J7: =MAX(G7-F7,0) -> 0 | K7: 1.053 | L7: Newly declined | M7: No linelist entries yet. Confirm a data-entry person is assigned and start entry. Was on track in May: check that data-entry staff are in place. | P7: Not started
A8: BANNU | B8: P1 – No entries | C8: DOMEL | D8: BIZEN KHEL 1 | E8: 36105003 | F8: 89 | G8: 0 | H8: =IF(F8>0,G8/F8,"n/a") -> 0 | I8: =MAX(F8-G8,0) -> 89 | J8: =MAX(G8-F8,0) -> 0 | K8: 0 | L8: Persistent low | M8: No linelist entries yet. Confirm a data-entry person is assigned and start entry. Low in May too: repeat problem, escalate to district. | P8: Not started
A9: BANNU | B9: P3 – Verify: over-entry | C9: DOMEL | D9: ASPERKA WAZIRAN | E9: 36105002 | F9: 60 | G9: 174 | H9: =IF(F9>0,G9/F9,"n/a") -> 2.9 | I9: =MAX(F9-G9,0) -> 0 | J9: =MAX(G9-F9,0) -> 114 | K9: 0 | L9: Recovered | M9: Entries exceed the IDIMS figure by more than 10%. Check for duplicate entries and cross-check the IDIMS number. | P9: Not started
A10: BANNU | B10: P3 – Verify: over-entry | C10: KAKKI | D10: KAKKI 2 | E10: 36106003 | F10: 99 | G10: 212 | H10: =IF(F10>0,G10/F10,"n/a") -> 2.141 | I10: =MAX(F10-G10,0) -> 0 | J10: =MAX(G10-F10,0) -> 113 | K10: 0.568 | L10: Recovered | M10: Entries exceed the IDIMS figure by more than 10%. Check for duplicate entries and cross-check the IDIMS number. | P10: Not started
A11: BANNU | B11: P3 – Verify: over-entry | C11: BANNU | D11: SIKANDAR KHEL BALLA | E11: 36101033 | F11: 122 | G11: 157 | H11: =IF(F11>0,G11/F11,"n/a") -> 1.287 | I11: =MAX(F11-G11,0) -> 0 | J11: =MAX(G11-F11,0) -> 35 | K11: 0.556 | L11: Recovered | M11: Entries exceed the IDIMS figure by more than 10%. Check for duplicate entries and cross-check the IDIMS number. | P11: Not started
A12: BANNU | B12: P3 – Verify: over-entry | C12: BAKAKHEL | D12: MOMAND KHEL | E12: 36103005 | F12: 77 | G12: 110 | H12: =IF(F12>0,G12/F12,"n/a") -> 1.429 | I12: =MAX(F12-G12,0) -> 0 | J12: =MAX(G12-F12,0) -> 33 | K12: 1.011 | L12: Stable (80%+ both) | M12: Entries exceed the IDIMS figure by more than 10%. Check for duplicate entries and cross-check the IDIMS number. | P12: Not started
A13: BANNU | B13: P3 – Verify: over-entry | C13: WAZIR | D13: HINDI KHEL | E13: 36102011 | F13: 24 | G13: 39 | H13: =IF(F13>0,G13/F13,"n/a") -> 1.625 | I13: =MAX(F13-G13,0) -> 0 | J13: =MAX(G13-F13,0) -> 15 | K13: 1 | L13: Stable (80%+ both) | M13: Entries exceed the IDIMS figure by more than 10%. Check for duplicate entries and cross-check the IDIMS number. | P13: Not started
A14: BANNU | B14: P3 – Verify: over-entry | C14: WAZIR | D14: SAIN TANGA | E14: 36102006 | F14: 16 | G14: 29 | H14: =IF(F14>0,G14/F14,"n/a") -> 1.812 | I14: =MAX(F14-G14,0) -> 0 | J14: =MAX(G14-F14,0) -> 13 | K14: 0.864 | L14: Stable (80%+ both) | M14: Entries exceed the IDIMS figure by more than 10%. Check for duplicate entries and cross-check the IDIMS number. | P14: Not started
A15: BANNU | B15: P3 – Verify: over-entry | C15: BAKAKHEL | D15: NARMI KHEL | E15: 36103006 | F15: 10 | G15: 22 | H15: =IF(F15>0,G15/F15,"n/a") -> 2.2 | I15: =MAX(F15-G15,0) -> 0 | J15: =MAX(G15-F15,0) -> 12 | K15: 0 | L15: Recovered | M15: Entries exceed the IDIMS figure by more than 10%. Check for duplicate entries and cross-check the IDIMS number. | P15: Not started
A16: BANNU | B16: P3 – Verify: over-entry | C16: BANNU | D16: DAUD SHAH | E16: 36101009 | F16: 61 | G16: 69 | H16: =IF(F16>0,G16/F16,"n/a") -> 1.131 | I16: =MAX(F16-G16,0) -> 0 | J16: =MAX(G16-F16,0) -> 8 | K16: 0.809 | L16: Stable (80%+ both) | M16: Entries exceed the IDIMS figure by more than 10%. Check for duplicate entries and cross-check the IDIMS number. | P16: Not started
... A42: KHYBER | B42: P3 – Verify: over-entry | C42: LANDI KOTAL | D42: MIRDAD KHEL | E42: 33404069 | F42: 48 | G42: 63 | H42: =IF(F42>0,G42/F42,"n/a") -> 1.312 | I42: =MAX(F42-G42,0) -> 0 | J42: =MAX(G42-F42,0) -> 15 | K42: 0.951 | L42: Stable (80%+ both) | M42: Entries exceed the IDIMS figure by more than 10%. Check for duplicate entries and cross-check the IDIMS number. | P42: Not started
A43: KHYBER | B43: P3 – Verify: no IDIMS figure | C43: TIRAH MAIDAN | D43: SHALOBAR TIRAH | E43: 33405006 | F43: 0 | G43: 9 | H43: =IF(F43>0,G43/F43,"n/a") -> n/a | I43: =MAX(F43-G43,0) -> 0 | J43: =MAX(G43-F43,0) -> 9 | K43: n/a | L43: Not comparable | M43: Linelist has entries but IDIMS reports 0 ZDs. Verify IDIMS reporting for this UC. | P43: Not started
A44: KHYBER | B44: P3 – Verify: no IDIMS figure | C44: TIRAH MAIDAN | D44: ZAKHAKHEL TIRAH | E44: 33405007 | F44: 0 | G44: 6 | H44: =IF(F44>0,G44/F44,"n/a") -> n/a | I44: =MAX(F44-G44,0) -> 0 | J44: =MAX(G44-F44,0) -> 6 | K44: n/a | L44: Not comparable | M44: Linelist has entries but IDIMS reports 0 ZDs. Verify IDIMS reporting for this UC. | P44: Not started
A45: KHYBER | B45: P3 – Verify: over-entry | C45: BARA | D45: MILWARD B | E45: 33401114 | F45: 30 | G45: 33 | H45: =IF(F45>0,G45/F45,"n/a") -> 1.1 | I45: =MAX(F45-G45,0) -> 0 | J45: =MAX(G45-F45,0) -> 3 | K45: 1 | L45: Stable (80%+ both) | M45: Entries exceed the IDIMS figure by more than 10%. Check for duplicate entries and cross-check the IDIMS number. | P45: Not started
A46: KHYBER | B46: P3 – Verify: over-entry | C46: LANDI KOTAL | D46: TORKHAM | E46: 33404078 | F46: 13 | G46: 16 | H46: =IF(F46>0,G46/F46,"n/a") -> 1.231 | I46: =MAX(F46-G46,0) -> 0 | J46: =MAX(G46-F46,0) -> 3 | K46: 0.286 | L46: Recovered | M46: Entries exceed the IDIMS figure by more than 10%. Check for duplicate entries and cross-check the IDIMS number. | P46: Not started
A47: KHYBER | B47: P4 – Low (50–80%) | C47: LANDI KOTAL | D47: LOE SHALMAN A | E47: 33404067 | F47: 65 | G47: 46 | H47: =IF(F47>0,G47/F47,"n/a") -> 0.708 | I47: =MAX(F47-G47,0) -> 19 | J47: =MAX(G47-F47,0) -> 0 | K47: 1.026 | L47: Newly declined | M47: Complete the remaining linelist entries. Was on track in May: check that data-entry staff are in place. | P47: Not started
A48: KHYBER | B48: P4 – Low (50–80%) | C48: LANDI KOTAL | D48: LOE SHALMAN B | E48: 33404068 | F48: 60 | G48: 47 | H48: =IF(F48>0,G48/F48,"n/a") -> 0.783 | I48: =MAX(F48-G48,0) -> 13 | J48: =MAX(G48-F48,0) -> 0 | K48: 1 | L48: Newly declined | M48: Complete the remaining linelist entries. Was on track in May: check that data-entry staff are in place. | P48: Not started
A49: LAKKIMRWT | B49: P3 – Verify: over-entry | C49: BETTANI | D49: CHECHANDI SAMAN | E49: 36204007 | F49: 55 | G49: 99 | H49: =IF(F49>0,G49/F49,"n/a") -> 1.8 | I49: =MAX(F49-G49,0) -> 0 | J49: =MAX(G49-F49,0) -> 44 | K49: 1 | L49: Stable (80%+ both) | M49: Entries exceed the IDIMS figure by more than 10%. Check for duplicate entries and cross-check the IDIMS number. | P49: Not started
A50: LAKKIMRWT | B50: P3 – Verify: over-entry | C50: SERAI NAURANG | D50: BAKHMAL AHMAD ZAI | E50: 36203022 | F50: 120 | G50: 146 | H50: =IF(F50>0,G50/F50,"n/a") -> 1.217 | I50: =MAX(F50-G50,0) -> 0 | J50: =MAX(G50-F50,0) -> 26 | K50: 1 | L50: Stable (80%+ both) | M50: Entries exceed the IDIMS figure by more than 10%. Check for duplicate entries and cross-check the IDIMS number. | P50: Not started
A51: LAKKIMRWT | B51: P3 – Verify: over-entry | C51: BETTANI | D51: SHEMALA | E51: 36204005 | F51: 168 | G51: 185 | H51: =IF(F51>0,G51/F51,"n/a") -> 1.101 | I51: =MAX(F51-G51,0) -> 0 | J51: =MAX(G51-F51,0) -> 17 | K51: 1 | L51: Stable (80%+ both) | M51: Entries exceed the IDIMS figure by more than 10%. Check for duplicate entries and cross-check the IDIMS number. | P51: Not started
A52: LAKKIMRWT | B52: P3 – Verify: over-entry | C52: BETTANI | D52: GABBAR BAGH | E52: 36204011 | F52: 44 | G52: 57 | H52: =IF(F52>0,G52/F52,"n/a") -> 1.295 | I52: =MAX(F52-G52,0) -> 0 | J52: =MAX(G52-F52,0) -> 13 | K52: 1 | L52: Stable (80%+ both) | M52: Entries exceed the IDIMS figure by more than 10%. Check for duplicate entries and cross-check the IDIMS number. | P52: Not started
A53: LAKKIMRWT | B53: P3 – Verify: over-entry | C53: BETTANI | D53: WATEEN SAR | E53: 36204009 | F53: 17 | G53: 21 | H53: =IF(F53>0,G53/F53,"n/a") -> 1.235 | I53: =MAX(F53-G53,0) -> 0 | J53: =MAX(G53-F53,0) -> 4 | K53: 1 | L53: Stable (80%+ both) | M53: Entries exceed the IDIMS figure by more than 10%. Check for duplicate entries and cross-check the IDIMS number. | P53: Not started
A54: LAKKIMRWT | B54: P4 – Low (50–80%) | C54: LAKKI MARWAT | D54: AHMADKHEL | E54: 36202023 | F54: 85 | G54: 47 | H54: =IF(F54>0,G54/F54,"n/a") -> 0.553 | I54: =MAX(F54-G54,0) -> 38 | J54: =MAX(G54-F54,0) -> 0 | K54: 1 | L54: Newly declined | M54: Complete the remaining linelist entries. Was on track in May: check that data-entry staff are in place. | P54: Not started
A55: LAKKIMRWT | B55: P4 – Low (50–80%) | C55: LAKKI MARWAT | D55: DERATANG | E55: 36202030 | F55: 138 | G55: 110 | H55: =IF(F55>0,G55/F55,"n/a") -> 0.797 | I55: =MAX(F55-G55,0) -> 28 | J55: =MAX(G55-F55,0) -> 0 | K55: 1 | L55: Newly declined | M55: Complete the remaining linelist entries. Was on track in May: check that data-entry staff are in place. | P55: Not started
A56: LAKKIMRWT | B56: P4 – Low (50–80%) | C56: GHAZNI KHEL | D56: GHAZNIKHEL | E56: 36205003 | F56: 110 | G56: 84 | H56: =IF(F56>0,G56/F56,"n/a") -> 0.764 | I56: =MAX(F56-G56,0) -> 26 | J56: =MAX(G56-F56,0) -> 0 | K56: 1 | L56: Newly declined | M56: Complete the remaining linelist entries. Was on track in May: check that data-entry staff are in place. | P56: Not started
... A84: WAZIR-N | B84: P1 – No entries | C84: MIR ALI | D84: MIR ALI 5 | E84: 36401036 | F84: 24 | G84: 0 | H84: =IF(F84>0,G84/F84,"n/a") -> 0 | I84: =MAX(F84-G84,0) -> 24 | J84: =MAX(G84-F84,0) -> 0 | K84: 1 | L84: Newly declined | M84: No linelist entries yet. Confirm a data-entry person is assigned and start entry. Was on track in May: check that data-entry staff are in place. | P84: Not started
A85: WAZIR-N | B85: P1 – No entries | C85: SPINWAM | D85: SPINWAM 2 | E85: 36409002 | F85: 9 | G85: 0 | H85: =IF(F85>0,G85/F85,"n/a") -> 0 | I85: =MAX(F85-G85,0) -> 9 | J85: =MAX(G85-F85,0) -> 0 | K85: n/a | L85: Not comparable | M85: No linelist entries yet. Confirm a data-entry person is assigned and start entry. | P85: Not started
A86: WAZIR-N | B86: P1 – No entries | C86: SHAWA | D86: SHAWA 1 | E86: 36408001 | F86: 8 | G86: 0 | H86: =IF(F86>0,G86/F86,"n/a") -> 0 | I86: =MAX(F86-G86,0) -> 8 | J86: =MAX(G86-F86,0) -> 0 | K86: n/a | L86: Not comparable | M86: No linelist entries yet. Confirm a data-entry person is assigned and start entry. | P86: Not started
A87: WAZIR-N | B87: P1 – No entries | C87: SHAWA | D87: SHAWA 2 | E87: 36408002 | F87: 5 | G87: 0 | H87: =IF(F87>0,G87/F87,"n/a") -> 0 | I87: =MAX(F87-G87,0) -> 5 | J87: =MAX(G87-F87,0) -> 0 | K87: n/a | L87: Not comparable | M87: No linelist entries yet. Confirm a data-entry person is assigned and start entry. | P87: Not started
A88: WAZIR-N | B88: P2 – Critical (<50%) | C88: DATTAKHEL | D88: DATTA KHEL 1 | E88: 36404001 | F88: 32 | G88: 8 | H88: =IF(F88>0,G88/F88,"n/a") -> 0.25 | I88: =MAX(F88-G88,0) -> 24 | J88: =MAX(G88-F88,0) -> 0 | K88: 1 | L88: Newly declined | M88: Less than half entered. Complete the remaining linelist entries. Was on track in May: check that data-entry staff are in place. | P88: Not started
A89: WAZIR-N | B89: P3 – Verify: over-entry | C89: MIRAN SHAH | D89: MIRAN SHAH 1 | E89: 36402042 | F89: 69 | G89: 165 | H89: =IF(F89>0,G89/F89,"n/a") -> 2.391 | I89: =MAX(F89-G89,0) -> 0 | J89: =MAX(G89-F89,0) -> 96 | K89: 1 | L89: Stable (80%+ both) | M89: Entries exceed the IDIMS figure by more than 10%. Check for duplicate entries and cross-check the IDIMS number. | P89: Not started
A90: WAZIR-N | B90: P3 – Verify: no IDIMS figure | C90: MIR ALI | D90: MIR ALI 6 | E90: 36401037 | F90: 0 | G90: 52 | H90: =IF(F90>0,G90/F90,"n/a") -> n/a | I90: =MAX(F90-G90,0) -> 0 | J90: =MAX(G90-F90,0) -> 52 | K90: n/a | L90: Not comparable | M90: Linelist has entries but IDIMS reports 0 ZDs. Verify IDIMS reporting for this UC. | P90: Not started
A91: WAZIR-N | B91: P3 – Verify: over-entry | C91: DATTAKHEL | D91: DATTA KHEL 2 | E91: 36404002 | F91: 74 | G91: 92 | H91: =IF(F91>0,G91/F91,"n/a") -> 1.243 | I91: =MAX(F91-G91,0) -> 0 | J91: =MAX(G91-F91,0) -> 18 | K91: 1 | L91: Stable (80%+ both) | M91: Entries exceed the IDIMS figure by more than 10%. Check for duplicate entries and cross-check the IDIMS number. | P91: Not started
A92: WAZIR-N | B92: P3 – Verify: over-entry | C92: MIRAN SHAH | D92: MIRAN SHAH 2 | E92: 36402043 | F92: 22 | G92: 38 | H92: =IF(F92>0,G92/F92,"n/a") -> 1.727 | I92: =MAX(F92-G92,0) -> 0 | J92: =MAX(G92-F92,0) -> 16 | K92: 1 | L92: Stable (80%+ both) | M92: Entries exceed the IDIMS figure by more than 10%. Check for duplicate entries and cross-check the IDIMS number. | P92: Not started
A93: WAZIR-N | B93: P3 – Verify: over-entry | C93: DOSSALI | D93: DOSALI 1 | E93: 36405001 | F93: 21 | G93: 29 | H93: =IF(F93>0,G93/F93,"n/a") -> 1.381 | I93: =MAX(F93-G93,0) -> 0 | J93: =MAX(G93-F93,0) -> 8 | K93: 1 | L93: Stable (80%+ both) | M93: Entries exceed the IDIMS figure by more than 10%. Check for duplicate entries and cross-check the IDIMS number. | P93: Not started
...

Sheet BANNU
A1: BANNU – Zero Dose Linelist Follow-up (SNID Sept 2026)
A2: District completion 3,747 of 4,205 = 89.1% · 23 of 57 UCs need follow-up · 748 children still to enter · 5 persistent low since May · Please fill the green columns and return
A4: Priority | B4: Tehsil | C4: UC | D4: UC Code | E4: ZD Reported | F4: ZD Linelist | G4: Completion % | H4: Children to enter | I4: Excess entries | J4: May completion % | K4: Trend May→Sept | L4: Action required | M4: Responsible person | N4: Target date | O4: Status | P4: Remarks
A5: P1 – No entries | B5: KAKKI | C5: KAKKI 1 | D5: 36106002 | E5: 135 | F5: 0 | G5: =IF(E5>0,F5/E5,"n/a") -> 0 | H5: =MAX(E5-F5,0) -> 135 | I5: =MAX(F5-E5,0) -> 0 | J5: 0.979 | K5: Newly declined | L5: No linelist entries yet. Confirm a data-entry person is assigned and start entry. Was on track in May: check that data-entry staff are in place. | O5: Not started
A6: P1 – No entries | B6: BANNU | C6: LALO ZAI | D6: 36101023 | E6: 120 | F6: 0 | G6: =IF(E6>0,F6/E6,"n/a") -> 0 | H6: =MAX(E6-F6,0) -> 120 | I6: =MAX(F6-E6,0) -> 0 | J6: 1 | K6: Newly declined | L6: No linelist entries yet. Confirm a data-entry person is assigned and start entry. Was on track in May: check that data-entry staff are in place. | O6: Not started
A7: P1 – No entries | B7: KAKKI | C7: NAR SHUKRULLAH | D7: 36106006 | E7: 111 | F7: 0 | G7: =IF(E7>0,F7/E7,"n/a") -> 0 | H7: =MAX(E7-F7,0) -> 111 | I7: =MAX(F7-E7,0) -> 0 | J7: 1.053 | K7: Newly declined | L7: No linelist entries yet. Confirm a data-entry person is assigned and start entry. Was on track in May: check that data-entry staff are in place. | O7: Not started
A8: P1 – No entries | B8: DOMEL | C8: BIZEN KHEL 1 | D8: 36105003 | E8: 89 | F8: 0 | G8: =IF(E8>0,F8/E8,"n/a") -> 0 | H8: =MAX(E8-F8,0) -> 89 | I8: =MAX(F8-E8,0) -> 0 | J8: 0 | K8: Persistent low | L8: No linelist entries yet. Confirm a data-entry person is assigned and start entry. Low in May too: repeat problem, escalate to district. | O8: Not started
A9: P3 – Verify: over-entry | B9: DOMEL | C9: ASPERKA WAZIRAN | D9: 36105002 | E9: 60 | F9: 174 | G9: =IF(E9>0,F9/E9,"n/a") -> 2.9 | H9: =MAX(E9-F9,0) -> 0 | I9: =MAX(F9-E9,0) -> 114 | J9: 0 | K9: Recovered | L9: Entries exceed the IDIMS figure by more than 10%. Check for duplicate entries and cross-check the IDIMS number. | O9: Not started
A10: P3 – Verify: over-entry | B10: KAKKI | C10: KAKKI 2 | D10: 36106003 | E10: 99 | F10: 212 | G10: =IF(E10>0,F10/E10,"n/a") -> 2.141 | H10: =MAX(E10-F10,0) -> 0 | I10: =MAX(F10-E10,0) -> 113 | J10: 0.568 | K10: Recovered | L10: Entries exceed the IDIMS figure by more than 10%. Check for duplicate entries and cross-check the IDIMS number. | O10: Not started
A11: P3 – Verify: over-entry | B11: BANNU | C11: SIKANDAR KHEL BALLA | D11: 36101033 | E11: 122 | F11: 157 | G11: =IF(E11>0,F11/E11,"n/a") -> 1.287 | H11: =MAX(E11-F11,0) -> 0 | I11: =MAX(F11-E11,0) -> 35 | J11: 0.556 | K11: Recovered | L11: Entries exceed the IDIMS figure by more than 10%. Check for duplicate entries and cross-check the IDIMS number. | O11: Not started
A12: P3 – Verify: over-entry | B12: BAKAKHEL | C12: MOMAND KHEL | D12: 36103005 | E12: 77 | F12: 110 | G12: =IF(E12>0,F12/E12,"n/a") -> 1.429 | H12: =MAX(E12-F12,0) -> 0 | I12: =MAX(F12-E12,0) -> 33 | J12: 1.011 | K12: Stable (80%+ both) | L12: Entries exceed the IDIMS figure by more than 10%. Check for duplicate entries and cross-check the IDIMS number. | O12: Not started
A13: P3 – Verify: over-entry | B13: WAZIR | C13: HINDI KHEL | D13: 36102011 | E13: 24 | F13: 39 | G13: =IF(E13>0,F13/E13,"n/a") -> 1.625 | H13: =MAX(E13-F13,0) -> 0 | I13: =MAX(F13-E13,0) -> 15 | J13: 1 | K13: Stable (80%+ both) | L13: Entries exceed the IDIMS figure by more than 10%. Check for duplicate entries and cross-check the IDIMS number. | O13: Not started
A14: P3 – Verify: over-entry | B14: WAZIR | C14: SAIN TANGA | D14: 36102006 | E14: 16 | F14: 29 | G14: =IF(E14>0,F14/E14,"n/a") -> 1.812 | H14: =MAX(E14-F14,0) -> 0 | I14: =MAX(F14-E14,0) -> 13 | J14: 0.864 | K14: Stable (80%+ both) | L14: Entries exceed the IDIMS figure by more than 10%. Check for duplicate entries and cross-check the IDIMS number. | O14: Not started
A15: P3 – Verify: over-entry | B15: BAKAKHEL | C15: NARMI KHEL | D15: 36103006 | E15: 10 | F15: 22 | G15: =IF(E15>0,F15/E15,"n/a") -> 2.2 | H15: =MAX(E15-F15,0) -> 0 | I15: =MAX(F15-E15,0) -> 12 | J15: 0 | K15: Recovered | L15: Entries exceed the IDIMS figure by more than 10%. Check for duplicate entries and cross-check the IDIMS number. | O15: Not started
A16: P3 – Verify: over-entry | B16: BANNU | C16: DAUD SHAH | D16: 36101009 | E16: 61 | F16: 69 | G16: =IF(E16>0,F16/E16,"n/a") -> 1.131 | H16: =MAX(E16-F16,0) -> 0 | I16: =MAX(F16-E16,0) -> 8 | J16: 0.809 | K16: Stable (80%+ both) | L16: Entries exceed the IDIMS figure by more than 10%. Check for duplicate entries and cross-check the IDIMS number. | O16: Not started
... A27: P4 – Low (50–80%) | B27: WAZIR | C27: ZARWAM | D27: 36102005 | E27: 48 | F27: 32 | G27: =IF(E27>0,F27/E27,"n/a") -> 0.667 | H27: =MAX(E27-F27,0) -> 16 | I27: =MAX(F27-E27,0) -> 0 | J27: 0 | K27: Persistent low | L27: Complete the remaining linelist entries. Also remove 3 duplicate record(s). Low in May too: repeat problem, escalate to district. | O27: Not started

Sheet DIKHAN
A1: DIKHAN – Zero Dose Linelist Follow-up (SNID Sept 2026)
A2: District completion 5,010 of 5,284 = 94.8% · 12 of 53 UCs need follow-up · 247 children still to enter · 3 persistent low since May · Please fill the green columns and return
A4: Priority | B4: Tehsil | C4: UC | D4: UC Code | E4: ZD Reported | F4: ZD Linelist | G4: Completion % | H4: Children to enter | I4: Excess entries | J4: May completion % | K4: Trend May→Sept | L4: Action required | M4: Responsible person | N4: Target date | O4: Status | P4: Remarks
A5: P1 – No entries | B5: DRABAN | C5: GARA ESSA KHAN | D5: 36003001 | E5: 92 | F5: 0 | G5: =IF(E5>0,F5/E5,"n/a") -> 0 | H5: =MAX(E5-F5,0) -> 92 | I5: =MAX(F5-E5,0) -> 0 | J5: 0.966 | K5: Newly declined | L5: No linelist entries yet. Confirm a data-entry person is assigned and start entry. Was on track in May: check that data-entry staff are in place. | O5: Not started
A6: P1 – No entries | B6: DARAZINDA | C6: KOHI BAHARA | D6: 36008004 | E6: 5 | F6: 0 | G6: =IF(E6>0,F6/E6,"n/a") -> 0 | H6: =MAX(E6-F6,0) -> 5 | I6: =MAX(F6-E6,0) -> 0 | J6: 2 | K6: Newly declined | L6: No linelist entries yet. Confirm a data-entry person is assigned and start entry. Was on track in May: check that data-entry staff are in place. | O6: Not started
A7: P2 – Critical (<50%) | B7: KULACHI | C7: LOONI | D7: 36005004 | E7: 38 | F7: 16 | G7: =IF(E7>0,F7/E7,"n/a") -> 0.421 | H7: =MAX(E7-F7,0) -> 22 | I7: =MAX(F7-E7,0) -> 0 | J7: 1 | K7: Newly declined | L7: Less than half entered. Complete the remaining linelist entries. Was on track in May: check that data-entry staff are in place. | O7: Not started
A8: P2 – Critical (<50%) | B8: DERA ISMAIL KHAN | C8: DERA CITY-I | D8: 36002002 | E8: 22 | F8: 10 | G8: =IF(E8>0,F8/E8,"n/a") -> 0.455 | H8: =MAX(E8-F8,0) -> 12 | I8: =MAX(F8-E8,0) -> 0 | J8: 0.333 | K8: Persistent low | L8: Less than half entered. Complete the remaining linelist entries. Low in May too: repeat problem, escalate to district. | O8: Not started
A9: P3 – Verify: over-entry | B9: DERA ISMAIL KHAN | C9: KURAI | D9: 36002014 | E9: 118 | F9: 136 | G9: =IF(E9>0,F9/E9,"n/a") -> 1.153 | H9: =MAX(E9-F9,0) -> 0 | I9: =MAX(F9-E9,0) -> 18 | J9: 0.967 | K9: Stable (80%+ both) | L9: Entries exceed the IDIMS figure by more than 10%. Check for duplicate entries and cross-check the IDIMS number. | O9: Not started
A10: P3 – Verify: over-entry | B10: DARAZINDA | C10: MORGA | D10: 36008005 | E10: 24 | F10: 30 | G10: =IF(E10>0,F10/E10,"n/a") -> 1.25 | H10: =MAX(E10-F10,0) -> 0 | I10: =MAX(F10-E10,0) -> 6 | J10: 1 | K10: Stable (80%+ both) | L10: Entries exceed the IDIMS figure by more than 10%. Check for duplicate entries and cross-check the IDIMS number. | O10: Not started
A11: P3 – Verify: duplicates | B11: PHARPUR | C11: KOTJAI | D11: 36007005 | E11: 86 | F11: 88 | G11: =IF(E11>0,F11/E11,"n/a") -> 1.023 | H11: =MAX(E11-F11,0) -> 0 | I11: =MAX(F11-E11,0) -> 2 | J11: 1 | K11: Stable (80%+ both) | L11: Duplicate records flagged in the report. Review and remove duplicates. | O11: Not started
A12: P4 – Low (50–80%) | B12: DERA ISMAIL KHAN | C12: RATTA KULACHI | D12: 36002017 | E12: 170 | F12: 132 | G12: =IF(E12>0,F12/E12,"n/a") -> 0.776 | H12: =MAX(E12-F12,0) -> 38 | I12: =MAX(F12-E12,0) -> 0 | J12: 1 | K12: Newly declined | L12: Complete the remaining linelist entries. Was on track in May: check that data-entry staff are in place. | O12: Not started
A13: P4 – Low (50–80%) | B13: DERA ISMAIL KHAN | C13: CHEHKAN | D13: 36002001 | E13: 140 | F13: 105 | G13: =IF(E13>0,F13/E13,"n/a") -> 0.75 | H13: =MAX(E13-F13,0) -> 35 | I13: =MAX(F13-E13,0) -> 0 | J13: 0.89 | K13: Newly declined | L13: Complete the remaining linelist entries. Was on track in May: check that data-entry staff are in place. | O13: Not started
A14: P4 – Low (50–80%) | B14: DERA ISMAIL KHAN | C14: DERA CITY-V | D14: 36002006 | E14: 72 | F14: 49 | G14: =IF(E14>0,F14/E14,"n/a") -> 0.681 | H14: =MAX(E14-F14,0) -> 23 | I14: =MAX(F14-E14,0) -> 0 | J14: 0.532 | K14: Persistent low | L14: Complete the remaining linelist entries. Low in May too: repeat problem, escalate to district. | O14: Not started
A15: P4 – Low (50–80%) | B15: DERA ISMAIL KHAN | C15: DERA CITY-II | D15: 36002003 | E15: 57 | F15: 45 | G15: =IF(E15>0,F15/E15,"n/a") -> 0.789 | H15: =MAX(E15-F15,0) -> 12 | I15: =MAX(F15-E15,0) -> 0 | J15: 0.455 | K15: Persistent low | L15: Complete the remaining linelist entries. Low in May too: repeat problem, escalate to district. | O15: Not started
A16: P4 – Low (50–80%) | B16: DERA ISMAIL KHAN | C16: DERA CITY-III | D16: 36002004 | E16: 25 | F16: 17 | G16: =IF(E16>0,F16/E16,"n/a") -> 0.68 | H16: =MAX(E16-F16,0) -> 8 | I16: =MAX(F16-E16,0) -> 0 | J16: 0.846 | K16: Newly declined | L16: Complete the remaining linelist entries. Was on track in May: check that data-entry staff are in place. | O16: Not started

Sheet KHYBER
A1: KHYBER – Zero Dose Linelist Follow-up (SNID Sept 2026)
A2: District completion 1,863 of 1,850 = 100.7% · 9 of 53 UCs need follow-up · 35 children still to enter · 0 persistent low since May · Please fill the green columns and return
A4: Priority | B4: Tehsil | C4: UC | D4: UC Code | E4: ZD Reported | F4: ZD Linelist | G4: Completion % | H4: Children to enter | I4: Excess entries | J4: May completion % | K4: Trend May→Sept | L4: Action required | M4: Responsible person | N4: Target date | O4: Status | P4: Remarks
A5: P1 – No entries | B5: TIRAH MAIDAN | C5: PAGDARA | D5: 33405009 | E5: 3 | F5: 0 | G5: =IF(E5>0,F5/E5,"n/a") -> 0 | H5: =MAX(E5-F5,0) -> 3 | I5: =MAX(F5-E5,0) -> 0 | J5: 1 | K5: Newly declined | L5: No linelist entries yet. Confirm a data-entry person is assigned and start entry. Was on track in May: check that data-entry staff are in place. | O5: Not started
A6: P3 – Verify: over-entry | B6: BARA | C6: AJAB TALAB | D6: 33401103 | E6: 72 | F6: 89 | G6: =IF(E6>0,F6/E6,"n/a") -> 1.236 | H6: =MAX(E6-F6,0) -> 0 | I6: =MAX(F6-E6,0) -> 17 | J6: 0.957 | K6: Stable (80%+ both) | L6: Entries exceed the IDIMS figure by more than 10%. Check for duplicate entries and cross-check the IDIMS number. | O6: Not started
A7: P3 – Verify: over-entry | B7: LANDI KOTAL | C7: MIRDAD KHEL | D7: 33404069 | E7: 48 | F7: 63 | G7: =IF(E7>0,F7/E7,"n/a") -> 1.312 | H7: =MAX(E7-F7,0) -> 0 | I7: =MAX(F7-E7,0) -> 15 | J7: 0.951 | K7: Stable (80%+ both) | L7: Entries exceed the IDIMS figure by more than 10%. Check for duplicate entries and cross-check the IDIMS number. | O7: Not started
A8: P3 – Verify: no IDIMS figure | B8: TIRAH MAIDAN | C8: SHALOBAR TIRAH | D8: 33405006 | E8: 0 | F8: 9 | G8: =IF(E8>0,F8/E8,"n/a") -> n/a | H8: =MAX(E8-F8,0) -> 0 | I8: =MAX(F8-E8,0) -> 9 | J8: n/a | K8: Not comparable | L8: Linelist has entries but IDIMS reports 0 ZDs. Verify IDIMS reporting for this UC. | O8: Not started
A9: P3 – Verify: no IDIMS figure | B9: TIRAH MAIDAN | C9: ZAKHAKHEL TIRAH | D9: 33405007 | E9: 0 | F9: 6 | G9: =IF(E9>0,F9/E9,"n/a") -> n/a | H9: =MAX(E9-F9,0) -> 0 | I9: =MAX(F9-E9,0) -> 6 | J9: n/a | K9: Not comparable | L9: Linelist has entries but IDIMS reports 0 ZDs. Verify IDIMS reporting for this UC. | O9: Not started
A10: P3 – Verify: over-entry | B10: BARA | C10: MILWARD B | D10: 33401114 | E10: 30 | F10: 33 | G10: =IF(E10>0,F10/E10,"n/a") -> 1.1 | H10: =MAX(E10-F10,0) -> 0 | I10: =MAX(F10-E10,0) -> 3 | J10: 1 | K10: Stable (80%+ both) | L10: Entries exceed the IDIMS figure by more than 10%. Check for duplicate entries and cross-check the IDIMS number. | O10: Not started
A11: P3 – Verify: over-entry | B11: LANDI KOTAL | C11: TORKHAM | D11: 33404078 | E11: 13 | F11: 16 | G11: =IF(E11>0,F11/E11,"n/a") -> 1.231 | H11: =MAX(E11-F11,0) -> 0 | I11: =MAX(F11-E11,0) -> 3 | J11: 0.286 | K11: Recovered | L11: Entries exceed the IDIMS figure by more than 10%. Check for duplicate entries and cross-check the IDIMS number. | O11: Not started
A12: P4 – Low (50–80%) | B12: LANDI KOTAL | C12: LOE SHALMAN A | D12: 33404067 | E12: 65 | F12: 46 | G12: =IF(E12>0,F12/E12,"n/a") -> 0.708 | H12: =MAX(E12-F12,0) -> 19 | I12: =MAX(F12-E12,0) -> 0 | J12: 1.026 | K12: Newly declined | L12: Complete the remaining linelist entries. Was on track in May: check that data-entry staff are in place. | O12: Not started
A13: P4 – Low (50–80%) | B13: LANDI KOTAL | C13: LOE SHALMAN B | D13: 33404068 | E13: 60 | F13: 47 | G13: =IF(E13>0,F13/E13,"n/a") -> 0.783 | H13: =MAX(E13-F13,0) -> 13 | I13: =MAX(F13-E13,0) -> 0 | J13: 1 | K13: Newly declined | L13: Complete the remaining linelist entries. Was on track in May: check that data-entry staff are in place. | O13: Not started

Sheet LAKKIMRWT
A1: LAKKIMRWT – Zero Dose Linelist Follow-up (SNID Sept 2026)
A2: District completion 4,560 of 4,555 = 100.1% · 10 of 40 UCs need follow-up · 139 children still to enter · 0 persistent low since May · Please fill the green columns and return
A4: Priority | B4: Tehsil | C4: UC | D4: UC Code | E4: ZD Reported | F4: ZD Linelist | G4: Completion % | H4: Children to enter | I4: Excess entries | J4: May completion % | K4: Trend May→Sept | L4: Action required | M4: Responsible person | N4: Target date | O4: Status | P4: Remarks
A5: P3 – Verify: over-entry | B5: BETTANI | C5: CHECHANDI SAMAN | D5: 36204007 | E5: 55 | F5: 99 | G5: =IF(E5>0,F5/E5,"n/a") -> 1.8 | H5: =MAX(E5-F5,0) -> 0 | I5: =MAX(F5-E5,0) -> 44 | J5: 1 | K5: Stable (80%+ both) | L5: Entries exceed the IDIMS figure by more than 10%. Check for duplicate entries and cross-check the IDIMS number. | O5: Not started
A6: P3 – Verify: over-entry | B6: SERAI NAURANG | C6: BAKHMAL AHMAD ZAI | D6: 36203022 | E6: 120 | F6: 146 | G6: =IF(E6>0,F6/E6,"n/a") -> 1.217 | H6: =MAX(E6-F6,0) -> 0 | I6: =MAX(F6-E6,0) -> 26 | J6: 1 | K6: Stable (80%+ both) | L6: Entries exceed the IDIMS figure by more than 10%. Check for duplicate entries and cross-check the IDIMS number. | O6: Not started
A7: P3 – Verify: over-entry | B7: BETTANI | C7: SHEMALA | D7: 36204005 | E7: 168 | F7: 185 | G7: =IF(E7>0,F7/E7,"n/a") -> 1.101 | H7: =MAX(E7-F7,0) -> 0 | I7: =MAX(F7-E7,0) -> 17 | J7: 1 | K7: Stable (80%+ both) | L7: Entries exceed the IDIMS figure by more than 10%. Check for duplicate entries and cross-check the IDIMS number. | O7: Not started
A8: P3 – Verify: over-entry | B8: BETTANI | C8: GABBAR BAGH | D8: 36204011 | E8: 44 | F8: 57 | G8: =IF(E8>0,F8/E8,"n/a") -> 1.295 | H8: =MAX(E8-F8,0) -> 0 | I8: =MAX(F8-E8,0) -> 13 | J8: 1 | K8: Stable (80%+ both) | L8: Entries exceed the IDIMS figure by more than 10%. Check for duplicate entries and cross-check the IDIMS number. | O8: Not started
A9: P3 – Verify: over-entry | B9: BETTANI | C9: WATEEN SAR | D9: 36204009 | E9: 17 | F9: 21 | G9: =IF(E9>0,F9/E9,"n/a") -> 1.235 | H9: =MAX(E9-F9,0) -> 0 | I9: =MAX(F9-E9,0) -> 4 | J9: 1 | K9: Stable (80%+ both) | L9: Entries exceed the IDIMS figure by more than 10%. Check for duplicate entries and cross-check the IDIMS number. | O9: Not started
A10: P4 – Low (50–80%) | B10: LAKKI MARWAT | C10: AHMADKHEL | D10: 36202023 | E10: 85 | F10: 47 | G10: =IF(E10>0,F10/E10,"n/a") -> 0.553 | H10: =MAX(E10-F10,0) -> 38 | I10: =MAX(F10-E10,0) -> 0 | J10: 1 | K10: Newly declined | L10: Complete the remaining linelist entries. Was on track in May: check that data-entry staff are in place. | O10: Not started
A11: P4 – Low (50–80%) | B11: LAKKI MARWAT | C11: DERATANG | D11: 36202030 | E11: 138 | F11: 110 | G11: =IF(E11>0,F11/E11,"n/a") -> 0.797 | H11: =MAX(E11-F11,0) -> 28 | I11: =MAX(F11-E11,0) -> 0 | J11: 1 | K11: Newly declined | L11: Complete the remaining linelist entries. Was on track in May: check that data-entry staff are in place. | O11: Not started
A12: P4 – Low (50–80%) | B12: GHAZNI KHEL | C12: GHAZNIKHEL | D12: 36205003 | E12: 110 | F12: 84 | G12: =IF(E12>0,F12/E12,"n/a") -> 0.764 | H12: =MAX(E12-F12,0) -> 26 | I12: =MAX(F12-E12,0) -> 0 | J12: 1 | K12: Newly declined | L12: Complete the remaining linelist entries. Was on track in May: check that data-entry staff are in place. | O12: Not started
A13: P4 – Low (50–80%) | B13: LAKKI MARWAT | C13: BEGOKHEL | D13: 36202028 | E13: 110 | F13: 86 | G13: =IF(E13>0,F13/E13,"n/a") -> 0.782 | H13: =MAX(E13-F13,0) -> 24 | I13: =MAX(F13-E13,0) -> 0 | J13: 1 | K13: Newly declined | L13: Complete the remaining linelist entries. Was on track in May: check that data-entry staff are in place. | O13: Not started
A14: P4 – Low (50–80%) | B14: SERAI NAURANG | C14: GANDI | D14: 36203014 | E14: 55 | F14: 32 | G14: =IF(E14>0,F14/E14,"n/a") -> 0.582 | H14: =MAX(E14-F14,0) -> 23 | I14: =MAX(F14-E14,0) -> 0 | J14: 1 | K14: Newly declined | L14: Complete the remaining linelist entries. Was on track in May: check that data-entry staff are in place. | O14: Not started

Sheet PESHAWAR
A1: PESHAWAR – Zero Dose Linelist Follow-up (SNID Sept 2026)
A2: District completion 12,681 of 13,547 = 93.6% · 16 of 103 UCs need follow-up · 1,010 children still to enter · 9 persistent low since May · Please fill the green columns and return
A4: Priority | B4: Tehsil | C4: UC | D4: UC Code | E4: ZD Reported | F4: ZD Linelist | G4: Completion % | H4: Children to enter | I4: Excess entries | J4: May completion % | K4: Trend May→Sept | L4: Action required | M4: Responsible person | N4: Target date | O4: Status | P4: Remarks
A5: P1 – No entries | B5: CITY | C5: TEHKAL PAYAN | D5: 33004031 | E5: 353 | F5: 0 | G5: =IF(E5>0,F5/E5,"n/a") -> 0 | H5: =MAX(E5-F5,0) -> 353 | I5: =MAX(F5-E5,0) -> 0 | J5: 0.086 | K5: Persistent low | L5: No linelist entries yet. Confirm a data-entry person is assigned and start entry. Low in May too: repeat problem, escalate to district. | O5: Not started
A6: P1 – No entries | B6: SMT | C6: NOTHIA JADEED | D6: 33008010 | E6: 144 | F6: 0 | G6: =IF(E6>0,F6/E6,"n/a") -> 0 | H6: =MAX(E6-F6,0) -> 144 | I6: =MAX(F6-E6,0) -> 0 | J6: 0.388 | K6: Persistent low | L6: No linelist entries yet. Confirm a data-entry person is assigned and start entry. Low in May too: repeat problem, escalate to district. | O6: Not started
A7: P1 – No entries | B7: CITY | C7: TEHKAL PAYAN 2 IRRIG | D7: 33004032 | E7: 109 | F7: 0 | G7: =IF(E7>0,F7/E7,"n/a") -> 0 | H7: =MAX(E7-F7,0) -> 109 | I7: =MAX(F7-E7,0) -> 0 | J7: 0.4 | K7: Persistent low | L7: No linelist entries yet. Confirm a data-entry person is assigned and start entry. Low in May too: repeat problem, escalate to district. | O7: Not started
A8: P1 – No entries | B8: HASSAN KHEL | C8: FARIDI | D8: 33003001 | E8: 18 | F8: 0 | G8: =IF(E8>0,F8/E8,"n/a") -> 0 | H8: =MAX(E8-F8,0) -> 18 | I8: =MAX(F8-E8,0) -> 0 | J8: 1 | K8: Newly declined | L8: No linelist entries yet. Confirm a data-entry person is assigned and start entry. Was on track in May: check that data-entry staff are in place. | O8: Not started
A9: P1 – No entries | B9: CITY | C9: CANTT WARD 4 | D9: 33004006 | E9: 4 | F9: 0 | G9: =IF(E9>0,F9/E9,"n/a") -> 0 | H9: =MAX(E9-F9,0) -> 4 | I9: =MAX(F9-E9,0) -> 0 | J9: 1 | K9: Newly declined | L9: No linelist entries yet. Confirm a data-entry person is assigned and start entry. Was on track in May: check that data-entry staff are in place. | O9: Not started
A10: P3 – Verify: over-entry | B10: SADDAR | C10: SUREZAI PAYAN | D10: 33006012 | E10: 102 | F10: 253 | G10: =IF(E10>0,F10/E10,"n/a") -> 2.48 | H10: =MAX(E10-F10,0) -> 0 | I10: =MAX(F10-E10,0) -> 151 | J10: 0.432 | K10: Recovered | L10: Entries exceed the IDIMS figure by more than 10%. Check for duplicate entries and cross-check the IDIMS number. | O10: Not started
A11: P3 – Verify: over-entry | B11: SMT | C11: SHAHEEN MUSLIM TWN1 | D11: 33008012 | E11: 143 | F11: 278 | G11: =IF(E11>0,F11/E11,"n/a") -> 1.944 | H11: =MAX(E11-F11,0) -> 0 | I11: =MAX(F11-E11,0) -> 135 | J11: 0.685 | K11: Recovered | L11: Entries exceed the IDIMS figure by more than 10%. Check for duplicate entries and cross-check the IDIMS number. | O11: Not started
A12: P3 – Verify: over-entry | B12: CITY | C12: TEHKAL BALA | D12: 33004030 | E12: 217 | F12: 240 | G12: =IF(E12>0,F12/E12,"n/a") -> 1.106 | H12: =MAX(E12-F12,0) -> 0 | I12: =MAX(F12-E12,0) -> 23 | J12: 0.364 | K12: Recovered | L12: Entries exceed the IDIMS figure by more than 10%. Check for duplicate entries and cross-check the IDIMS number. | O12: Not started
A13: P3 – Verify: over-entry | B13: CITY | C13: SHAHI BAGH | D13: 33004027 | E13: 30 | F13: 33 | G13: =IF(E13>0,F13/E13,"n/a") -> 1.1 | H13: =MAX(E13-F13,0) -> 0 | I13: =MAX(F13-E13,0) -> 3 | J13: 0.955 | K13: Stable (80%+ both) | L13: Entries exceed the IDIMS figure by more than 10%. Check for duplicate entries and cross-check the IDIMS number. | O13: Not started
A14: P4 – Low (50–80%) | B14: MATTANI | C14: SHEIKHAN | D14: 33005008 | E14: 277 | F14: 146 | G14: =IF(E14>0,F14/E14,"n/a") -> 0.527 | H14: =MAX(E14-F14,0) -> 131 | I14: =MAX(F14-E14,0) -> 0 | J14: 0.32 | K14: Persistent low | L14: Complete the remaining linelist entries. Low in May too: repeat problem, escalate to district. | O14: Not started
A15: P4 – Low (50–80%) | B15: MATTANI | C15: SARBAND | D15: 33005006 | E15: 298 | F15: 189 | G15: =IF(E15>0,F15/E15,"n/a") -> 0.634 | H15: =MAX(E15-F15,0) -> 109 | I15: =MAX(F15-E15,0) -> 0 | J15: 0.45 | K15: Persistent low | L15: Complete the remaining linelist entries. Low in May too: repeat problem, escalate to district. | O15: Not started
A16: P4 – Low (50–80%) | B16: MATTANI | C16: SHEIKH MOHAMMADI | D16: 33005007 | E16: 215 | F16: 151 | G16: =IF(E16>0,F16/E16,"n/a") -> 0.702 | H16: =MAX(E16-F16,0) -> 64 | I16: =MAX(F16-E16,0) -> 0 | J16: 0.227 | K16: Persistent low | L16: Complete the remaining linelist entries. Low in May too: repeat problem, escalate to district. | O16: Not started
... A20: P4 – Low (50–80%) | B20: CITY | C20: CANTT WARD 3 | D20: 33004005 | E20: 8 | F20: 5 | G20: =IF(E20>0,F20/E20,"n/a") -> 0.625 | H20: =MAX(E20-F20,0) -> 3 | I20: =MAX(F20-E20,0) -> 0 | J20: 1 | K20: Newly declined | L20: Complete the remaining linelist entries. Was on track in May: check that data-entry staff are in place. | O20: Not started

Sheet TANK
A1: TANK – Zero Dose Linelist Follow-up (SNID Sept 2026)
A2: District completion 871 of 967 = 90.1% · 7 of 22 UCs need follow-up · 150 children still to enter · 0 persistent low since May · Please fill the green columns and return
A4: Priority | B4: Tehsil | C4: UC | D4: UC Code | E4: ZD Reported | F4: ZD Linelist | G4: Completion % | H4: Children to enter | I4: Excess entries | J4: May completion % | K4: Trend May→Sept | L4: Action required | M4: Responsible person | N4: Target date | O4: Status | P4: Remarks
A5: P1 – No entries | B5: TANK | C5: DABARA | D5: 36302002 | E5: 81 | F5: 0 | G5: =IF(E5>0,F5/E5,"n/a") -> 0 | H5: =MAX(E5-F5,0) -> 81 | I5: =MAX(F5-E5,0) -> 0 | J5: 1.118 | K5: Newly declined | L5: No linelist entries yet. Confirm a data-entry person is assigned and start entry. Was on track in May: check that data-entry staff are in place. | O5: Not started
A6: P1 – No entries | B6: JANDOLA | C6: PING A | D6: 36303004 | E6: 7 | F6: 0 | G6: =IF(E6>0,F6/E6,"n/a") -> 0 | H6: =MAX(E6-F6,0) -> 7 | I6: =MAX(F6-E6,0) -> 0 | J6: 1 | K6: Newly declined | L6: No linelist entries yet. Confirm a data-entry person is assigned and start entry. Was on track in May: check that data-entry staff are in place. | O6: Not started
A7: P1 – No entries | B7: JANDOLA | C7: PIR TANGY | D7: 36303006 | E7: 4 | F7: 0 | G7: =IF(E7>0,F7/E7,"n/a") -> 0 | H7: =MAX(E7-F7,0) -> 4 | I7: =MAX(F7-E7,0) -> 0 | J7: 1 | K7: Newly declined | L7: No linelist entries yet. Confirm a data-entry person is assigned and start entry. Was on track in May: check that data-entry staff are in place. | O7: Not started
A8: P2 – Critical (<50%) | B8: TANK | C8: AMAKHEL | D8: 36302001 | E8: 62 | F8: 15 | G8: =IF(E8>0,F8/E8,"n/a") -> 0.242 | H8: =MAX(E8-F8,0) -> 47 | I8: =MAX(F8-E8,0) -> 0 | J8: 0.97 | K8: Newly declined | L8: Less than half entered. Complete the remaining linelist entries. Was on track in May: check that data-entry staff are in place. | O8: Not started
A9: P3 – Verify: over-entry | B9: TANK | C9: SARANGZOONA | D9: 36302010 | E9: 18 | F9: 88 | G9: =IF(E9>0,F9/E9,"n/a") -> 4.889 | H9: =MAX(E9-F9,0) -> 0 | I9: =MAX(F9-E9,0) -> 70 | J9: 0.583 | K9: Recovered | L9: Entries exceed the IDIMS figure by more than 10%. Check for duplicate entries and cross-check the IDIMS number. | O9: Not started
A10: P4 – Low (50–80%) | B10: TANK | C10: WARASPOON | D10: 36302016 | E10: 18 | F10: 12 | G10: =IF(E10>0,F10/E10,"n/a") -> 0.667 | H10: =MAX(E10-F10,0) -> 6 | I10: =MAX(F10-E10,0) -> 0 | J10: 1 | K10: Newly declined | L10: Complete the remaining linelist entries. Was on track in May: check that data-entry staff are in place. | O10: Not started
A11: P4 – Low (50–80%) | B11: JANDOLA | C11: PING B | D11: 36303005 | E11: 23 | F11: 18 | G11: =IF(E11>0,F11/E11,"n/a") -> 0.783 | H11: =MAX(E11-F11,0) -> 5 | I11: =MAX(F11-E11,0) -> 0 | J11: 1 | K11: Newly declined | L11: Complete the remaining linelist entries. Was on track in May: check that data-entry staff are in place. | O11: Not started

Sheet WAZIR-N
A1: WAZIR-N – Zero Dose Linelist Follow-up (SNID Sept 2026)
A2: District completion 537 of 492 = 109.1% · 15 of 23 UCs need follow-up · 155 children still to enter · 0 persistent low since May · Please fill the green columns and return
A4: Priority | B4: Tehsil | C4: UC | D4: UC Code | E4: ZD Reported | F4: ZD Linelist | G4: Completion % | H4: Children to enter | I4: Excess entries | J4: May completion % | K4: Trend May→Sept | L4: Action required | M4: Responsible person | N4: Target date | O4: Status | P4: Remarks
A5: P1 – No entries | B5: DATTAKHEL | C5: DATTA KHEL 3 | D5: 36404003 | E5: 29 | F5: 0 | G5: =IF(E5>0,F5/E5,"n/a") -> 0 | H5: =MAX(E5-F5,0) -> 29 | I5: =MAX(F5-E5,0) -> 0 | J5: 1 | K5: Newly declined | L5: No linelist entries yet. Confirm a data-entry person is assigned and start entry. Was on track in May: check that data-entry staff are in place. | O5: Not started
A6: P1 – No entries | B6: MIR ALI | C6: MIR ALI 7 | D6: 36401038 | E6: 28 | F6: 0 | G6: =IF(E6>0,F6/E6,"n/a") -> 0 | H6: =MAX(E6-F6,0) -> 28 | I6: =MAX(F6-E6,0) -> 0 | J6: 1 | K6: Newly declined | L6: No linelist entries yet. Confirm a data-entry person is assigned and start entry. Was on track in May: check that data-entry staff are in place. | O6: Not started
A7: P1 – No entries | B7: MIR ALI | C7: MIR ALI 5 | D7: 36401036 | E7: 24 | F7: 0 | G7: =IF(E7>0,F7/E7,"n/a") -> 0 | H7: =MAX(E7-F7,0) -> 24 | I7: =MAX(F7-E7,0) -> 0 | J7: 1 | K7: Newly declined | L7: No linelist entries yet. Confirm a data-entry person is assigned and start entry. Was on track in May: check that data-entry staff are in place. | O7: Not started
A8: P1 – No entries | B8: SPINWAM | C8: SPINWAM 2 | D8: 36409002 | E8: 9 | F8: 0 | G8: =IF(E8>0,F8/E8,"n/a") -> 0 | H8: =MAX(E8-F8,0) -> 9 | I8: =MAX(F8-E8,0) -> 0 | J8: n/a | K8: Not comparable | L8: No linelist entries yet. Confirm a data-entry person is assigned and start entry. | O8: Not started
A9: P1 – No entries | B9: SHAWA | C9: SHAWA 1 | D9: 36408001 | E9: 8 | F9: 0 | G9: =IF(E9>0,F9/E9,"n/a") -> 0 | H9: =MAX(E9-F9,0) -> 8 | I9: =MAX(F9-E9,0) -> 0 | J9: n/a | K9: Not comparable | L9: No linelist entries yet. Confirm a data-entry person is assigned and start entry. | O9: Not started
A10: P1 – No entries | B10: SHAWA | C10: SHAWA 2 | D10: 36408002 | E10: 5 | F10: 0 | G10: =IF(E10>0,F10/E10,"n/a") -> 0 | H10: =MAX(E10-F10,0) -> 5 | I10: =MAX(F10-E10,0) -> 0 | J10: n/a | K10: Not comparable | L10: No linelist entries yet. Confirm a data-entry person is assigned and start entry. | O10: Not started
A11: P2 – Critical (<50%) | B11: DATTAKHEL | C11: DATTA KHEL 1 | D11: 36404001 | E11: 32 | F11: 8 | G11: =IF(E11>0,F11/E11,"n/a") -> 0.25 | H11: =MAX(E11-F11,0) -> 24 | I11: =MAX(F11-E11,0) -> 0 | J11: 1 | K11: Newly declined | L11: Less than half entered. Complete the remaining linelist entries. Was on track in May: check that data-entry staff are in place. | O11: Not started
A12: P3 – Verify: over-entry | B12: MIRAN SHAH | C12: MIRAN SHAH 1 | D12: 36402042 | E12: 69 | F12: 165 | G12: =IF(E12>0,F12/E12,"n/a") -> 2.391 | H12: =MAX(E12-F12,0) -> 0 | I12: =MAX(F12-E12,0) -> 96 | J12: 1 | K12: Stable (80%+ both) | L12: Entries exceed the IDIMS figure by more than 10%. Check for duplicate entries and cross-check the IDIMS number. | O12: Not started
A13: P3 – Verify: no IDIMS figure | B13: MIR ALI | C13: MIR ALI 6 | D13: 36401037 | E13: 0 | F13: 52 | G13: =IF(E13>0,F13/E13,"n/a") -> n/a | H13: =MAX(E13-F13,0) -> 0 | I13: =MAX(F13-E13,0) -> 52 | J13: n/a | K13: Not comparable | L13: Linelist has entries but IDIMS reports 0 ZDs. Verify IDIMS reporting for this UC. | O13: Not started
A14: P3 – Verify: over-entry | B14: DATTAKHEL | C14: DATTA KHEL 2 | D14: 36404002 | E14: 74 | F14: 92 | G14: =IF(E14>0,F14/E14,"n/a") -> 1.243 | H14: =MAX(E14-F14,0) -> 0 | I14: =MAX(F14-E14,0) -> 18 | J14: 1 | K14: Stable (80%+ both) | L14: Entries exceed the IDIMS figure by more than 10%. Check for duplicate entries and cross-check the IDIMS number. | O14: Not started
A15: P3 – Verify: over-entry | B15: MIRAN SHAH | C15: MIRAN SHAH 2 | D15: 36402043 | E15: 22 | F15: 38 | G15: =IF(E15>0,F15/E15,"n/a") -> 1.727 | H15: =MAX(E15-F15,0) -> 0 | I15: =MAX(F15-E15,0) -> 16 | J15: 1 | K15: Stable (80%+ both) | L15: Entries exceed the IDIMS figure by more than 10%. Check for duplicate entries and cross-check the IDIMS number. | O15: Not started
A16: P3 – Verify: over-entry | B16: DOSSALI | C16: DOSALI 1 | D16: 36405001 | E16: 21 | F16: 29 | G16: =IF(E16>0,F16/E16,"n/a") -> 1.381 | H16: =MAX(E16-F16,0) -> 0 | I16: =MAX(F16-E16,0) -> 8 | J16: 1 | K16: Stable (80%+ both) | L16: Entries exceed the IDIMS figure by more than 10%. Check for duplicate entries and cross-check the IDIMS number. | O16: Not started
A17: P3 – Verify: no IDIMS figure | B17: DOSSALI | C17: DOSALI 2 | D17: 36405002 | E17: 0 | F17: 8 | G17: =IF(E17>0,F17/E17,"n/a") -> n/a | H17: =MAX(E17-F17,0) -> 0 | I17: =MAX(F17-E17,0) -> 8 | J17: 1 | K17: Not comparable | L17: Linelist has entries but IDIMS reports 0 ZDs. Verify IDIMS reporting for this UC. | O17: Not started
A18: P3 – Verify: over-entry | B18: MIR ALI | C18: MIR ALI 1 | D18: 36401032 | E18: 2 | F18: 5 | G18: =IF(E18>0,F18/E18,"n/a") -> 2.5 | H18: =MAX(E18-F18,0) -> 0 | I18: =MAX(F18-E18,0) -> 3 | J18: 1 | K18: Stable (80%+ both) | L18: Entries exceed the IDIMS figure by more than 10%. Check for duplicate entries and cross-check the IDIMS number. | O18: Not started
A19: P4 – Low (50–80%) | B19: MIRAN SHAH | C19: MIRAN SHAH 3 | D19: 36402044 | E19: 63 | F19: 35 | G19: =IF(E19>0,F19/E19,"n/a") -> 0.556 | H19: =MAX(E19-F19,0) -> 28 | I19: =MAX(F19-E19,0) -> 0 | J19: 1 | K19: Newly declined | L19: Complete the remaining linelist entries. Was on track in May: check that data-entry staff are in place. | O19: Not started

Sheet WAZIR-S Lower
A1: WAZIR-S Lower – Zero Dose Linelist Follow-up (SNID Sept 2026)
A2: District completion 517 of 572 = 90.4% · 20 of 36 UCs need follow-up · 112 children still to enter · 2 persistent low since May · Please fill the green columns and return
A4: Priority | B4: Tehsil | C4: UC | D4: UC Code | E4: ZD Reported | F4: ZD Linelist | G4: Completion % | H4: Children to enter | I4: Excess entries | J4: May completion % | K4: Trend May→Sept | L4: Action required | M4: Responsible person | N4: Target date | O4: Status | P4: Remarks
A5: P1 – No entries | B5: TOI KHULLA | C5: Zar Mellon | D5: 36703003 | E5: 32 | F5: 0 | G5: =IF(E5>0,F5/E5,"n/a") -> 0 | H5: =MAX(E5-F5,0) -> 32 | I5: =MAX(F5-E5,0) -> 0 | J5: 7 | K5: Newly declined | L5: No linelist entries yet. Confirm a data-entry person is assigned and start entry. Was on track in May: check that data-entry staff are in place. | O5: Not started
A6: P1 – No entries | B6: WANA | C6: Zari Noor | D6: 36704015 | E6: 27 | F6: 0 | G6: =IF(E6>0,F6/E6,"n/a") -> 0 | H6: =MAX(E6-F6,0) -> 27 | I6: =MAX(F6-E6,0) -> 0 | J6: 1 | K6: Newly declined | L6: No linelist entries yet. Confirm a data-entry person is assigned and start entry. Was on track in May: check that data-entry staff are in place. | O6: Not started
